
A module that was compiled using NumPy 1.x cannot be run in
NumPy 2.2.4 as it may crash. To support both 1.x and 2.x
versions of NumPy, modules must be compiled with NumPy 2.0.
Some module may need to rebuild instead e.g. with 'pybind11>=2.12'.

If you are a user of the module, the easiest solution will be to
downgrade to 'numpy<2' or try to upgrade the affected module.
We expect that some modules will need time to support NumPy 2.

Traceback (most recent call last):  File "/home/users/sv226/everything/caramba/inference.py", line 2, in <module>
    from transformers import AutoModelForCausalLM, AutoTokenizer, AutoModel
  File "/home/users/sv226/.local/lib/python3.10/site-packages/transformers/utils/import_utils.py", line 1965, in __getattr__
    value = getattr(module, name)
  File "/home/users/sv226/.local/lib/python3.10/site-packages/transformers/utils/import_utils.py", line 1964, in __getattr__
    module = self._get_module(self._class_to_module[name])
  File "/home/users/sv226/.local/lib/python3.10/site-packages/transformers/utils/import_utils.py", line 1976, in _get_module
    return importlib.import_module("." + module_name, self.__name__)
  File "/usr/lib/python3.10/importlib/__init__.py", line 126, in import_module
    return _bootstrap._gcd_import(name[level:], package, level)
  File "/home/users/sv226/.local/lib/python3.10/site-packages/transformers/models/auto/modeling_auto.py", line 22, in <module>
    from .auto_factory import (
  File "/home/users/sv226/.local/lib/python3.10/site-packages/transformers/models/auto/auto_factory.py", line 40, in <module>
    from ...generation import GenerationMixin
  File "/home/users/sv226/.local/lib/python3.10/site-packages/transformers/utils/import_utils.py", line 1964, in __getattr__
    module = self._get_module(self._class_to_module[name])
  File "/home/users/sv226/.local/lib/python3.10/site-packages/transformers/utils/import_utils.py", line 1976, in _get_module
    return importlib.import_module("." + module_name, self.__name__)
  File "/usr/lib/python3.10/importlib/__init__.py", line 126, in import_module
    return _bootstrap._gcd_import(name[level:], package, level)
  File "/home/users/sv226/.local/lib/python3.10/site-packages/transformers/generation/utils.py", line 30, in <module>
    from transformers.generation.candidate_generator import AssistantVocabTranslatorCache
  File "/home/users/sv226/.local/lib/python3.10/site-packages/transformers/generation/candidate_generator.py", line 27, in <module>
    from sklearn.metrics import roc_curve
  File "/home/users/sv226/.local/lib/python3.10/site-packages/sklearn/__init__.py", line 73, in <module>
    from .base import clone  # noqa: E402
  File "/home/users/sv226/.local/lib/python3.10/site-packages/sklearn/base.py", line 19, in <module>
    from .utils._estimator_html_repr import _HTMLDocumentationLinkMixin, estimator_html_repr
  File "/home/users/sv226/.local/lib/python3.10/site-packages/sklearn/utils/__init__.py", line 15, in <module>
    from ._chunking import gen_batches, gen_even_slices
  File "/home/users/sv226/.local/lib/python3.10/site-packages/sklearn/utils/_chunking.py", line 11, in <module>
    from ._param_validation import Interval, validate_params
  File "/home/users/sv226/.local/lib/python3.10/site-packages/sklearn/utils/_param_validation.py", line 17, in <module>
    from .validation import _is_arraylike_not_scalar
  File "/home/users/sv226/.local/lib/python3.10/site-packages/sklearn/utils/validation.py", line 21, in <module>
    from ..utils._array_api import _asarray_with_order, _is_numpy_namespace, get_namespace
  File "/home/users/sv226/.local/lib/python3.10/site-packages/sklearn/utils/_array_api.py", line 17, in <module>
    from .fixes import parse_version
  File "/home/users/sv226/.local/lib/python3.10/site-packages/sklearn/utils/fixes.py", line 20, in <module>
    import pandas as pd
  File "/home/users/sv226/.local/lib/python3.10/site-packages/pandas/__init__.py", line 49, in <module>
    from pandas.core.api import (
  File "/home/users/sv226/.local/lib/python3.10/site-packages/pandas/core/api.py", line 28, in <module>
    from pandas.core.arrays import Categorical
  File "/home/users/sv226/.local/lib/python3.10/site-packages/pandas/core/arrays/__init__.py", line 1, in <module>
    from pandas.core.arrays.arrow import ArrowExtensionArray
  File "/home/users/sv226/.local/lib/python3.10/site-packages/pandas/core/arrays/arrow/__init__.py", line 5, in <module>
    from pandas.core.arrays.arrow.array import ArrowExtensionArray
  File "/home/users/sv226/.local/lib/python3.10/site-packages/pandas/core/arrays/arrow/array.py", line 50, in <module>
    from pandas.core import (
  File "/home/users/sv226/.local/lib/python3.10/site-packages/pandas/core/ops/__init__.py", line 8, in <module>
    from pandas.core.ops.array_ops import (
  File "/home/users/sv226/.local/lib/python3.10/site-packages/pandas/core/ops/array_ops.py", line 56, in <module>
    from pandas.core.computation import expressions
  File "/home/users/sv226/.local/lib/python3.10/site-packages/pandas/core/computation/expressions.py", line 21, in <module>
    from pandas.core.computation.check import NUMEXPR_INSTALLED
  File "/home/users/sv226/.local/lib/python3.10/site-packages/pandas/core/computation/check.py", line 5, in <module>
    ne = import_optional_dependency("numexpr", errors="warn")
  File "/home/users/sv226/.local/lib/python3.10/site-packages/pandas/compat/_optional.py", line 135, in import_optional_dependency
    module = importlib.import_module(name)
  File "/usr/lib/python3.10/importlib/__init__.py", line 126, in import_module
    return _bootstrap._gcd_import(name[level:], package, level)
  File "/usr/lib/python3/dist-packages/numexpr/__init__.py", line 24, in <module>
    from numexpr.interpreter import MAX_THREADS, use_vml, __BLOCK_SIZE1__
AttributeError: _ARRAY_API not found
/home/users/sv226/.local/lib/python3.10/site-packages/matplotlib/projections/__init__.py:63: UserWarning: Unable to import Axes3D. This may be due to multiple versions of Matplotlib being installed (e.g. as a system package and as a pip package). As a result, the 3D projection is not available.
  warnings.warn("Unable to import Axes3D. This may be due to multiple versions of "
Traceback (most recent call last):
  File "/home/users/sv226/everything/caramba/inference.py", line 238, in <module>
    main()
  File "/home/users/sv226/everything/caramba/inference.py", line 214, in main
    start_movie_id = int(sys.argv[1])  
ValueError: invalid literal for int() with base 10: '../caramba_jtd.out'

A module that was compiled using NumPy 1.x cannot be run in
NumPy 2.2.4 as it may crash. To support both 1.x and 2.x
versions of NumPy, modules must be compiled with NumPy 2.0.
Some module may need to rebuild instead e.g. with 'pybind11>=2.12'.

If you are a user of the module, the easiest solution will be to
downgrade to 'numpy<2' or try to upgrade the affected module.
We expect that some modules will need time to support NumPy 2.

Traceback (most recent call last):  File "/home/users/sv226/everything/caramba/train_predictor.py", line 5, in <module>
    from sklearn.linear_model import LogisticRegression
  File "/home/users/sv226/.local/lib/python3.10/site-packages/sklearn/__init__.py", line 73, in <module>
    from .base import clone  # noqa: E402
  File "/home/users/sv226/.local/lib/python3.10/site-packages/sklearn/base.py", line 19, in <module>
    from .utils._estimator_html_repr import _HTMLDocumentationLinkMixin, estimator_html_repr
  File "/home/users/sv226/.local/lib/python3.10/site-packages/sklearn/utils/__init__.py", line 15, in <module>
    from ._chunking import gen_batches, gen_even_slices
  File "/home/users/sv226/.local/lib/python3.10/site-packages/sklearn/utils/_chunking.py", line 11, in <module>
    from ._param_validation import Interval, validate_params
  File "/home/users/sv226/.local/lib/python3.10/site-packages/sklearn/utils/_param_validation.py", line 17, in <module>
    from .validation import _is_arraylike_not_scalar
  File "/home/users/sv226/.local/lib/python3.10/site-packages/sklearn/utils/validation.py", line 21, in <module>
    from ..utils._array_api import _asarray_with_order, _is_numpy_namespace, get_namespace
  File "/home/users/sv226/.local/lib/python3.10/site-packages/sklearn/utils/_array_api.py", line 17, in <module>
    from .fixes import parse_version
  File "/home/users/sv226/.local/lib/python3.10/site-packages/sklearn/utils/fixes.py", line 20, in <module>
    import pandas as pd
  File "/home/users/sv226/.local/lib/python3.10/site-packages/pandas/__init__.py", line 49, in <module>
    from pandas.core.api import (
  File "/home/users/sv226/.local/lib/python3.10/site-packages/pandas/core/api.py", line 28, in <module>
    from pandas.core.arrays import Categorical
  File "/home/users/sv226/.local/lib/python3.10/site-packages/pandas/core/arrays/__init__.py", line 1, in <module>
    from pandas.core.arrays.arrow import ArrowExtensionArray
  File "/home/users/sv226/.local/lib/python3.10/site-packages/pandas/core/arrays/arrow/__init__.py", line 5, in <module>
    from pandas.core.arrays.arrow.array import ArrowExtensionArray
  File "/home/users/sv226/.local/lib/python3.10/site-packages/pandas/core/arrays/arrow/array.py", line 50, in <module>
    from pandas.core import (
  File "/home/users/sv226/.local/lib/python3.10/site-packages/pandas/core/ops/__init__.py", line 8, in <module>
    from pandas.core.ops.array_ops import (
  File "/home/users/sv226/.local/lib/python3.10/site-packages/pandas/core/ops/array_ops.py", line 56, in <module>
    from pandas.core.computation import expressions
  File "/home/users/sv226/.local/lib/python3.10/site-packages/pandas/core/computation/expressions.py", line 21, in <module>
    from pandas.core.computation.check import NUMEXPR_INSTALLED
  File "/home/users/sv226/.local/lib/python3.10/site-packages/pandas/core/computation/check.py", line 5, in <module>
    ne = import_optional_dependency("numexpr", errors="warn")
  File "/home/users/sv226/.local/lib/python3.10/site-packages/pandas/compat/_optional.py", line 135, in import_optional_dependency
    module = importlib.import_module(name)
  File "/usr/lib/python3.10/importlib/__init__.py", line 126, in import_module
    return _bootstrap._gcd_import(name[level:], package, level)
  File "/usr/lib/python3/dist-packages/numexpr/__init__.py", line 24, in <module>
    from numexpr.interpreter import MAX_THREADS, use_vml, __BLOCK_SIZE1__
AttributeError: _ARRAY_API not found
/home/users/sv226/.local/lib/python3.10/site-packages/matplotlib/projections/__init__.py:63: UserWarning: Unable to import Axes3D. This may be due to multiple versions of Matplotlib being installed (e.g. as a system package and as a pip package). As a result, the 3D projection is not available.
  warnings.warn("Unable to import Axes3D. This may be due to multiple versions of "
Traceback (most recent call last):
  File "/home/users/sv226/.local/lib/python3.10/site-packages/huggingface_hub/utils/_http.py", line 406, in hf_raise_for_status
    response.raise_for_status()
  File "/home/users/sv226/.local/lib/python3.10/site-packages/requests/models.py", line 1024, in raise_for_status
    raise HTTPError(http_error_msg, response=self)
requests.exceptions.HTTPError: 404 Client Error: Not Found for url: https://huggingface.co/500/resolve/main/config.json

The above exception was the direct cause of the following exception:

Traceback (most recent call last):
  File "/home/users/sv226/.local/lib/python3.10/site-packages/transformers/utils/hub.py", line 424, in cached_files
    hf_hub_download(
  File "/home/users/sv226/.local/lib/python3.10/site-packages/huggingface_hub/utils/_validators.py", line 114, in _inner_fn
    return fn(*args, **kwargs)
  File "/home/users/sv226/.local/lib/python3.10/site-packages/huggingface_hub/file_download.py", line 860, in hf_hub_download
    return _hf_hub_download_to_cache_dir(
  File "/home/users/sv226/.local/lib/python3.10/site-packages/huggingface_hub/file_download.py", line 967, in _hf_hub_download_to_cache_dir
    _raise_on_head_call_error(head_call_error, force_download, local_files_only)
  File "/home/users/sv226/.local/lib/python3.10/site-packages/huggingface_hub/file_download.py", line 1482, in _raise_on_head_call_error
    raise head_call_error
  File "/home/users/sv226/.local/lib/python3.10/site-packages/huggingface_hub/file_download.py", line 1374, in _get_metadata_or_catch_error
    metadata = get_hf_file_metadata(
  File "/home/users/sv226/.local/lib/python3.10/site-packages/huggingface_hub/utils/_validators.py", line 114, in _inner_fn
    return fn(*args, **kwargs)
  File "/home/users/sv226/.local/lib/python3.10/site-packages/huggingface_hub/file_download.py", line 1294, in get_hf_file_metadata
    r = _request_wrapper(
  File "/home/users/sv226/.local/lib/python3.10/site-packages/huggingface_hub/file_download.py", line 278, in _request_wrapper
    response = _request_wrapper(
  File "/home/users/sv226/.local/lib/python3.10/site-packages/huggingface_hub/file_download.py", line 302, in _request_wrapper
    hf_raise_for_status(response)
  File "/home/users/sv226/.local/lib/python3.10/site-packages/huggingface_hub/utils/_http.py", line 454, in hf_raise_for_status
    raise _format(RepositoryNotFoundError, message, response) from e
huggingface_hub.errors.RepositoryNotFoundError: 404 Client Error. (Request ID: Root=1-67f695de-26dbd80d3bbdf7cc462dff9c;9a3d4784-f5fa-4ca2-bfef-6b56db730198)

Repository Not Found for url: https://huggingface.co/500/resolve/main/config.json.
Please make sure you specified the correct `repo_id` and `repo_type`.
If you are trying to access a private or gated repo, make sure you are authenticated.

The above exception was the direct cause of the following exception:

Traceback (most recent call last):
  File "/home/users/sv226/everything/caramba/train_predictor.py", line 196, in <module>
    main()
  File "/home/users/sv226/everything/caramba/train_predictor.py", line 178, in main
    _, tokenizer = load_embedding_model_and_tokenizer(model_name)
  File "/home/users/sv226/everything/caramba/inference.py", line 54, in load_embedding_model_and_tokenizer
    model = AutoModel.from_pretrained(
  File "/home/users/sv226/.local/lib/python3.10/site-packages/transformers/models/auto/auto_factory.py", line 492, in from_pretrained
    resolved_config_file = cached_file(
  File "/home/users/sv226/.local/lib/python3.10/site-packages/transformers/utils/hub.py", line 266, in cached_file
    file = cached_files(path_or_repo_id=path_or_repo_id, filenames=[filename], **kwargs)
  File "/home/users/sv226/.local/lib/python3.10/site-packages/transformers/utils/hub.py", line 456, in cached_files
    raise EnvironmentError(
OSError: 500 is not a local folder and is not a valid model identifier listed on 'https://huggingface.co/models'
If this is a private repository, make sure to pass a token having permission to this repo either by logging in with `huggingface-cli login` or by passing `token=<your_token>`

A module that was compiled using NumPy 1.x cannot be run in
NumPy 2.2.4 as it may crash. To support both 1.x and 2.x
versions of NumPy, modules must be compiled with NumPy 2.0.
Some module may need to rebuild instead e.g. with 'pybind11>=2.12'.

If you are a user of the module, the easiest solution will be to
downgrade to 'numpy<2' or try to upgrade the affected module.
We expect that some modules will need time to support NumPy 2.

Traceback (most recent call last):  File "/home/users/sv226/everything/caramba/evaluate_perplexity.py", line 4, in <module>
    from transformers import AutoModel, AutoTokenizer, AutoModelForCausalLM
  File "/home/users/sv226/.local/lib/python3.10/site-packages/transformers/utils/import_utils.py", line 1965, in __getattr__
    value = getattr(module, name)
  File "/home/users/sv226/.local/lib/python3.10/site-packages/transformers/utils/import_utils.py", line 1964, in __getattr__
    module = self._get_module(self._class_to_module[name])
  File "/home/users/sv226/.local/lib/python3.10/site-packages/transformers/utils/import_utils.py", line 1976, in _get_module
    return importlib.import_module("." + module_name, self.__name__)
  File "/usr/lib/python3.10/importlib/__init__.py", line 126, in import_module
    return _bootstrap._gcd_import(name[level:], package, level)
  File "/home/users/sv226/.local/lib/python3.10/site-packages/transformers/models/auto/modeling_auto.py", line 22, in <module>
    from .auto_factory import (
  File "/home/users/sv226/.local/lib/python3.10/site-packages/transformers/models/auto/auto_factory.py", line 40, in <module>
    from ...generation import GenerationMixin
  File "/home/users/sv226/.local/lib/python3.10/site-packages/transformers/utils/import_utils.py", line 1964, in __getattr__
    module = self._get_module(self._class_to_module[name])
  File "/home/users/sv226/.local/lib/python3.10/site-packages/transformers/utils/import_utils.py", line 1976, in _get_module
    return importlib.import_module("." + module_name, self.__name__)
  File "/usr/lib/python3.10/importlib/__init__.py", line 126, in import_module
    return _bootstrap._gcd_import(name[level:], package, level)
  File "/home/users/sv226/.local/lib/python3.10/site-packages/transformers/generation/utils.py", line 30, in <module>
    from transformers.generation.candidate_generator import AssistantVocabTranslatorCache
  File "/home/users/sv226/.local/lib/python3.10/site-packages/transformers/generation/candidate_generator.py", line 27, in <module>
    from sklearn.metrics import roc_curve
  File "/home/users/sv226/.local/lib/python3.10/site-packages/sklearn/__init__.py", line 73, in <module>
    from .base import clone  # noqa: E402
  File "/home/users/sv226/.local/lib/python3.10/site-packages/sklearn/base.py", line 19, in <module>
    from .utils._estimator_html_repr import _HTMLDocumentationLinkMixin, estimator_html_repr
  File "/home/users/sv226/.local/lib/python3.10/site-packages/sklearn/utils/__init__.py", line 15, in <module>
    from ._chunking import gen_batches, gen_even_slices
  File "/home/users/sv226/.local/lib/python3.10/site-packages/sklearn/utils/_chunking.py", line 11, in <module>
    from ._param_validation import Interval, validate_params
  File "/home/users/sv226/.local/lib/python3.10/site-packages/sklearn/utils/_param_validation.py", line 17, in <module>
    from .validation import _is_arraylike_not_scalar
  File "/home/users/sv226/.local/lib/python3.10/site-packages/sklearn/utils/validation.py", line 21, in <module>
    from ..utils._array_api import _asarray_with_order, _is_numpy_namespace, get_namespace
  File "/home/users/sv226/.local/lib/python3.10/site-packages/sklearn/utils/_array_api.py", line 17, in <module>
    from .fixes import parse_version
  File "/home/users/sv226/.local/lib/python3.10/site-packages/sklearn/utils/fixes.py", line 20, in <module>
    import pandas as pd
  File "/home/users/sv226/.local/lib/python3.10/site-packages/pandas/__init__.py", line 49, in <module>
    from pandas.core.api import (
  File "/home/users/sv226/.local/lib/python3.10/site-packages/pandas/core/api.py", line 28, in <module>
    from pandas.core.arrays import Categorical
  File "/home/users/sv226/.local/lib/python3.10/site-packages/pandas/core/arrays/__init__.py", line 1, in <module>
    from pandas.core.arrays.arrow import ArrowExtensionArray
  File "/home/users/sv226/.local/lib/python3.10/site-packages/pandas/core/arrays/arrow/__init__.py", line 5, in <module>
    from pandas.core.arrays.arrow.array import ArrowExtensionArray
  File "/home/users/sv226/.local/lib/python3.10/site-packages/pandas/core/arrays/arrow/array.py", line 50, in <module>
    from pandas.core import (
  File "/home/users/sv226/.local/lib/python3.10/site-packages/pandas/core/ops/__init__.py", line 8, in <module>
    from pandas.core.ops.array_ops import (
  File "/home/users/sv226/.local/lib/python3.10/site-packages/pandas/core/ops/array_ops.py", line 56, in <module>
    from pandas.core.computation import expressions
  File "/home/users/sv226/.local/lib/python3.10/site-packages/pandas/core/computation/expressions.py", line 21, in <module>
    from pandas.core.computation.check import NUMEXPR_INSTALLED
  File "/home/users/sv226/.local/lib/python3.10/site-packages/pandas/core/computation/check.py", line 5, in <module>
    ne = import_optional_dependency("numexpr", errors="warn")
  File "/home/users/sv226/.local/lib/python3.10/site-packages/pandas/compat/_optional.py", line 135, in import_optional_dependency
    module = importlib.import_module(name)
  File "/usr/lib/python3.10/importlib/__init__.py", line 126, in import_module
    return _bootstrap._gcd_import(name[level:], package, level)
  File "/usr/lib/python3/dist-packages/numexpr/__init__.py", line 24, in <module>
    from numexpr.interpreter import MAX_THREADS, use_vml, __BLOCK_SIZE1__
AttributeError: _ARRAY_API not found
/home/users/sv226/.local/lib/python3.10/site-packages/matplotlib/projections/__init__.py:63: UserWarning: Unable to import Axes3D. This may be due to multiple versions of Matplotlib being installed (e.g. as a system package and as a pip package). As a result, the 3D projection is not available.
  warnings.warn("Unable to import Axes3D. This may be due to multiple versions of "
Loading models...
Traceback (most recent call last):
  File "/home/users/sv226/.local/lib/python3.10/site-packages/huggingface_hub/utils/_http.py", line 406, in hf_raise_for_status
    response.raise_for_status()
  File "/home/users/sv226/.local/lib/python3.10/site-packages/requests/models.py", line 1024, in raise_for_status
    raise HTTPError(http_error_msg, response=self)
requests.exceptions.HTTPError: 404 Client Error: Not Found for url: https://huggingface.co/500/resolve/main/config.json

The above exception was the direct cause of the following exception:

Traceback (most recent call last):
  File "/home/users/sv226/.local/lib/python3.10/site-packages/transformers/utils/hub.py", line 424, in cached_files
    hf_hub_download(
  File "/home/users/sv226/.local/lib/python3.10/site-packages/huggingface_hub/utils/_validators.py", line 114, in _inner_fn
    return fn(*args, **kwargs)
  File "/home/users/sv226/.local/lib/python3.10/site-packages/huggingface_hub/file_download.py", line 860, in hf_hub_download
    return _hf_hub_download_to_cache_dir(
  File "/home/users/sv226/.local/lib/python3.10/site-packages/huggingface_hub/file_download.py", line 967, in _hf_hub_download_to_cache_dir
    _raise_on_head_call_error(head_call_error, force_download, local_files_only)
  File "/home/users/sv226/.local/lib/python3.10/site-packages/huggingface_hub/file_download.py", line 1482, in _raise_on_head_call_error
    raise head_call_error
  File "/home/users/sv226/.local/lib/python3.10/site-packages/huggingface_hub/file_download.py", line 1374, in _get_metadata_or_catch_error
    metadata = get_hf_file_metadata(
  File "/home/users/sv226/.local/lib/python3.10/site-packages/huggingface_hub/utils/_validators.py", line 114, in _inner_fn
    return fn(*args, **kwargs)
  File "/home/users/sv226/.local/lib/python3.10/site-packages/huggingface_hub/file_download.py", line 1294, in get_hf_file_metadata
    r = _request_wrapper(
  File "/home/users/sv226/.local/lib/python3.10/site-packages/huggingface_hub/file_download.py", line 278, in _request_wrapper
    response = _request_wrapper(
  File "/home/users/sv226/.local/lib/python3.10/site-packages/huggingface_hub/file_download.py", line 302, in _request_wrapper
    hf_raise_for_status(response)
  File "/home/users/sv226/.local/lib/python3.10/site-packages/huggingface_hub/utils/_http.py", line 454, in hf_raise_for_status
    raise _format(RepositoryNotFoundError, message, response) from e
huggingface_hub.errors.RepositoryNotFoundError: 404 Client Error. (Request ID: Root=1-67f695e7-1d63d5ed504422916e75d2f7;041c4085-e84a-435e-bcda-607a8e22655c)

Repository Not Found for url: https://huggingface.co/500/resolve/main/config.json.
Please make sure you specified the correct `repo_id` and `repo_type`.
If you are trying to access a private or gated repo, make sure you are authenticated.

The above exception was the direct cause of the following exception:

Traceback (most recent call last):
  File "/home/users/sv226/everything/caramba/evaluate_perplexity.py", line 281, in <module>
    main()
  File "/home/users/sv226/everything/caramba/evaluate_perplexity.py", line 227, in main
    model, tokenizer = load_embedding_model_and_tokenizer(model_name)
  File "/home/users/sv226/everything/caramba/inference.py", line 54, in load_embedding_model_and_tokenizer
    model = AutoModel.from_pretrained(
  File "/home/users/sv226/.local/lib/python3.10/site-packages/transformers/models/auto/auto_factory.py", line 492, in from_pretrained
    resolved_config_file = cached_file(
  File "/home/users/sv226/.local/lib/python3.10/site-packages/transformers/utils/hub.py", line 266, in cached_file
    file = cached_files(path_or_repo_id=path_or_repo_id, filenames=[filename], **kwargs)
  File "/home/users/sv226/.local/lib/python3.10/site-packages/transformers/utils/hub.py", line 456, in cached_files
    raise EnvironmentError(
OSError: 500 is not a local folder and is not a valid model identifier listed on 'https://huggingface.co/models'
If this is a private repository, make sure to pass a token having permission to this repo either by logging in with `huggingface-cli login` or by passing `token=<your_token>`
